Workbook
Name aa: INDEX(#REF!,MATCH(#REF!,#REF!,0),1):INDEX(#REF!,MATCH(#REF!,#REF!,0),1)
Name aaaa: INDEX(#REF!,MATCH(#REF!,#REF!,0),1):INDEX(#REF!,MATCH(#REF!,#REF!,0),1)
Name adwadwq: #REF!
Name Amazon_IST: INDEX(#REF!,MATCH(#REF!,#REF!,0),1):INDEX(#REF!,MATCH(#REF!,#REF!,0),1)
Name Amazon_Soll: INDEX(#REF!,MATCH(#REF!,#REF!,0),1):INDEX(#REF!,MATCH(#REF!,#REF!,0),1)
Name Anzeigewoche: #REF!
Name Artikelliste: #REF!
Name asdad: #REF!
Name asdadaqqwds: INDEX(#REF!,MATCH(#REF!,#REF!,0),1):INDEX(#REF!,MATCH(#REF!,#REF!,0),1)
Name asdasd: INDEX(#REF!,MATCH(#REF!,#REF!,0),1):INDEX(#REF!,COUNTA(#REF!),1)
Name asdasdad: INDEX(#REF!,MATCH(#REF!,#REF!,0),1):INDEX(#REF!,MATCH(#REF!,#REF!,0),1)
Name asdasdas: INDEX(#REF!,MATCH(#REF!,#REF!,0),1):INDEX(#REF!,MATCH(#REF!,#REF!,0),1)
Name asdasdasd: INDEX(#REF!,MATCH(#REF!,#REF!,0),1):INDEX(#REF!,MATCH(#REF!,#REF!,0),1)
Name asdawdqwf: INDEX(#REF!,MATCH(#REF!,#REF!,0),1):INDEX(#REF!,MATCH(#REF!,#REF!,0),1)
Name asdqwd: INDEX(#REF!,MATCH(#REF!,#REF!,0),1):INDEX(#REF!,MATCH(#REF!,#REF!,0),1)
Name asdqwdsqd: INDEX(#REF!,MATCH(#REF!,#REF!,0),1):INDEX(#REF!,MATCH(#REF!,#REF!,0),1)
Name asss: INDEX(#REF!,MATCH(#REF!,#REF!,0),1):INDEX(#REF!,MATCH(#REF!,#REF!,0),1)
Name BadRevAnteil: #REF!
Name BadSeasonHart: #REF!
Name BadSeasonWeich: #REF!
Name Batteries: #REF!
Name Battery: #REF!
Name CatL1: #REF!
Name CatL3: #REF!
Name circ: #REF!
Name cJahr: #REF!
Name cMonat: #REF!
Name ddda: #REF!:INDEX(#REF!,MATCH(#REF!,#REF!,0),1)
Name dddd: INDEX(#REF!,MATCH(#REF!,#REF!,0),1):INDEX(#REF!,MATCH(#REF!,#REF!,0),1)
Name EndeMonat: INDEX(#REF!,MATCH(#REF!,#REF!,0),1):INDEX(#REF!,COUNTA(#REF!),1)
Name Export_List_Ak: #REF!
Name Export_SKU_SAP: #REF!
Name Gesamt_Ist: INDEX(#REF!,MATCH(#REF!,#REF!,0),1):INDEX(#REF!,MATCH(#REF!,#REF!,0),1)
Name Gesamt_Soll: INDEX(#REF!,MATCH(#REF!,#REF!,0),1):INDEX(#REF!,MATCH(#REF!,#REF!,0),1)
Name Großkunden_Ist: INDEX(#REF!,MATCH(#REF!,#REF!,0),1):INDEX(#REF!,MATCH(#REF!,#REF!,0),1)
Name Großkunden_Soll: INDEX(#REF!,MATCH(#REF!,#REF!,0),1):INDEX(#REF!,MATCH(#REF!,#REF!,0),1)
Name hello: #REF!
Name HighPriceAnteil: #REF!
Name increments: #REF!
Name IoT: #REF!
Name IPX_Rating: #REF!
Name Jahr: #REF!
Name Kategorieliste: #REF!
Name Kennzeichnungs_Prozentsatz: #REF!
Name kjvcksaghdf: #REF!
Name Kleinkunden_Ceotra_Ist: INDEX(#REF!,MATCH(#REF!,#REF!,0),1):INDEX(#REF!,MATCH(#REF!,#REF!,0),1)
Name Kleinkunden_Ceotra_Soll: INDEX(#REF!,MATCH(#REF!,#REF!,0),1):INDEX(#REF!,MATCH(#REF!,#REF!,0),1)
Name Kleinkunden_Chaltec_Ist: INDEX(#REF!,MATCH(#REF!,#REF!,0),1):INDEX(#REF!,MATCH(#REF!,#REF!,0),1)
Name KleinkundenChal_Tec_Soll: INDEX(#REF!,MATCH(#REF!,#REF!,0),1):INDEX(#REF!,MATCH(#REF!,#REF!,0),1)
Name KT_Consulting_Soll: INDEX(#REF!,MATCH(#REF!,#REF!,0),1):INDEX(#REF!,MATCH(#REF!,#REF!,0),1)
Name KTConsulting_Ist: INDEX(#REF!,MATCH(#REF!,#REF!,0),1):INDEX(#REF!,MATCH(#REF!,#REF!,0),1)
Name L1Cat: #REF!
Name L3Cat: #REF!
Name list: #REF!
Name MA_Brand: OFFSET(#REF!,1,0,COUNTA(#REF!)-1)
Name Mitarbeiterliste: #REF!
Name Monat: #REF!
Name Monate: INDEX(#REF!,MATCH(#REF!,#REF!,0),1):INDEX(#REF!,MATCH(#REF!,#REF!,0),1)
Name OGP_Ist: INDEX(#REF!,MATCH(#REF!,#REF!,0),1):INDEX(#REF!,MATCH(#REF!,#REF!,0),1)
Name OGP_Soll: INDEX(#REF!,MATCH(#REF!,#REF!,0),1):INDEX(#REF!,MATCH(#REF!,#REF!,0),1)

Sheet Category Tree 5.0
B1: KLARSTEIN | Portfolio Planning v05 | Category Tree 5.0
B4: L1 | C4: L2 | D4: L3 | E4: L4 | F4: Index 5.0 | G4: PM | H4: Attributes File | I4: Part of Scope
B5: Climate | F5: =_xlfn.TEXTJOIN("-",TRUE,CatTree50[[#This Row],[L1]],CatTree50[[#This Row],[L2]],CatTree50[[#This Row],[L3]],CatTree50[[#This Row],[L4]]) -> Climate | H5: =_xlfn.XLOOKUP(CatTree50[[#This Row],[Index 5.0]],'Category List'!B:B,'Category List'!C:C,"")
B6: Climate | C6: Cooling | F6: =_xlfn.TEXTJOIN("-",TRUE,CatTree50[[#This Row],[L1]],CatTree50[[#This Row],[L2]],CatTree50[[#This Row],[L3]],CatTree50[[#This Row],[L4]]) -> Climate-Cooling | G6: Raquel Gonzalez Rodriguez | H6: =_xlfn.XLOOKUP(CatTree50[[#This Row],[Index 5.0]],'Category List'!B:B,'Category List'!C:C,"")
B7: Climate | C7: Cooling | D7: Accessories for Cooling | F7: =_xlfn.TEXTJOIN("-",TRUE,CatTree50[[#This Row],[L1]],CatTree50[[#This Row],[L2]],CatTree50[[#This Row],[L3]],CatTree50[[#This Row],[L4]]) -> Climate-Cooling-Accessories for Cooling | G7: Raquel Gonzalez Rodriguez | H7: =_xlfn.XLOOKUP(CatTree50[[#This Row],[Index 5.0]],'Category List'!B:B,'Category List'!C:C,"")
B8: Climate | C8: Cooling | D8: Mobile Air Conditioners | F8: =_xlfn.TEXTJOIN("-",TRUE,CatTree50[[#This Row],[L1]],CatTree50[[#This Row],[L2]],CatTree50[[#This Row],[L3]],CatTree50[[#This Row],[L4]]) -> Climate-Cooling-Mobile Air Conditioners | G8: Raquel Gonzalez Rodriguez | H8: =_xlfn.XLOOKUP(CatTree50[[#This Row],[Index 5.0]],'Category List'!B:B,'Category List'!C:C,"") -> Mobile Air Conditioners - Attributes V3.0.xlsx
B9: Climate | C9: Cooling | D9: Pedestal Fans | F9: =_xlfn.TEXTJOIN("-",TRUE,CatTree50[[#This Row],[L1]],CatTree50[[#This Row],[L2]],CatTree50[[#This Row],[L3]],CatTree50[[#This Row],[L4]]) -> Climate-Cooling-Pedestal Fans | G9: Raquel Gonzalez Rodriguez | H9: =_xlfn.XLOOKUP(CatTree50[[#This Row],[Index 5.0]],'Category List'!B:B,'Category List'!C:C,"") | I9: Done
B10: Climate | C10: Cooling | D10: Split Air Conditioners | F10: =_xlfn.TEXTJOIN("-",TRUE,CatTree50[[#This Row],[L1]],CatTree50[[#This Row],[L2]],CatTree50[[#This Row],[L3]],CatTree50[[#This Row],[L4]]) -> Climate-Cooling-Split Air Conditioners | G10: Raquel Gonzalez Rodriguez | H10: =_xlfn.XLOOKUP(CatTree50[[#This Row],[Index 5.0]],'Category List'!B:B,'Category List'!C:C,"")
B11: Climate | C11: Cooling | D11: Tower Fans | F11: =_xlfn.TEXTJOIN("-",TRUE,CatTree50[[#This Row],[L1]],CatTree50[[#This Row],[L2]],CatTree50[[#This Row],[L3]],CatTree50[[#This Row],[L4]]) -> Climate-Cooling-Tower Fans | G11: Raquel Gonzalez Rodriguez | H11: =_xlfn.XLOOKUP(CatTree50[[#This Row],[Index 5.0]],'Category List'!B:B,'Category List'!C:C,"") | I11: Done
B12: Climate | C12: Dehumidifiers | F12: =_xlfn.TEXTJOIN("-",TRUE,CatTree50[[#This Row],[L1]],CatTree50[[#This Row],[L2]],CatTree50[[#This Row],[L3]],CatTree50[[#This Row],[L4]]) -> Climate-Dehumidifiers | G12: Raquel Gonzalez Rodriguez | H12: =_xlfn.XLOOKUP(CatTree50[[#This Row],[Index 5.0]],'Category List'!B:B,'Category List'!C:C,"") | I12: Done
B13: Climate | C13: Indoor Heaters | F13: =_xlfn.TEXTJOIN("-",TRUE,CatTree50[[#This Row],[L1]],CatTree50[[#This Row],[L2]],CatTree50[[#This Row],[L3]],CatTree50[[#This Row],[L4]]) -> Climate-Indoor Heaters | G13: Raquel Gonzalez Rodriguez | H13: =_xlfn.XLOOKUP(CatTree50[[#This Row],[Index 5.0]],'Category List'!B:B,'Category List'!C:C,"") | I13: Exclude
B14: Climate | C14: Indoor Heaters | D14: Accessories for Indoor Heaters | F14: =_xlfn.TEXTJOIN("-",TRUE,CatTree50[[#This Row],[L1]],CatTree50[[#This Row],[L2]],CatTree50[[#This Row],[L3]],CatTree50[[#This Row],[L4]]) -> Climate-Indoor Heaters-Accessories for Indoor Heaters | G14: Raquel Gonzalez Rodriguez | H14: =_xlfn.XLOOKUP(CatTree50[[#This Row],[Index 5.0]],'Category List'!B:B,'Category List'!C:C,"") | I14: Exclude
B15: Climate | C15: Indoor Heaters | D15: Bathroom Radiators | F15: =_xlfn.TEXTJOIN("-",TRUE,CatTree50[[#This Row],[L1]],CatTree50[[#This Row],[L2]],CatTree50[[#This Row],[L3]],CatTree50[[#This Row],[L4]]) -> Climate-Indoor Heaters-Bathroom Radiators | G15: Raquel Gonzalez Rodriguez | H15: =_xlfn.XLOOKUP(CatTree50[[#This Row],[Index 5.0]],'Category List'!B:B,'Category List'!C:C,"") | I15: Exclude
B16: Climate | C16: Indoor Heaters | D16: Bathroom Radiators | E16: Infrared Radiators | F16: =_xlfn.TEXTJOIN("-",TRUE,CatTree50[[#This Row],[L1]],CatTree50[[#This Row],[L2]],CatTree50[[#This Row],[L3]],CatTree50[[#This Row],[L4]]) -> Climate-Indoor Heaters-Bathroom Radiators-Infrared Radiators | G16: Raquel Gonzalez Rodriguez | H16: =_xlfn.XLOOKUP(CatTree50[[#This Row],[Index 5.0]],'Category List'!B:B,'Category List'!C:C,"") -> Infrared Radiators - Attributes V3.0.xlsx | I16: Done
B17: Climate | C17: Indoor Heaters | D17: Bathroom Radiators | E17: Towel Radiators | F17: =_xlfn.TEXTJOIN("-",TRUE,CatTree50[[#This Row],[L1]],CatTree50[[#This Row],[L2]],CatTree50[[#This Row],[L3]],CatTree50[[#This Row],[L4]]) -> Climate-Indoor Heaters-Bathroom Radiators-Towel Radiators | G17: Raquel Gonzalez Rodriguez | H17: =_xlfn.XLOOKUP(CatTree50[[#This Row],[Index 5.0]],'Category List'!B:B,'Category List'!C:C,"") | I17: Done
B18: Climate | C18: Indoor Heaters | D18: Designer Radiators | F18: =_xlfn.TEXTJOIN("-",TRUE,CatTree50[[#This Row],[L1]],CatTree50[[#This Row],[L2]],CatTree50[[#This Row],[L3]],CatTree50[[#This Row],[L4]]) -> Climate-Indoor Heaters-Designer Radiators | G18: Raquel Gonzalez Rodriguez | H18: =_xlfn.XLOOKUP(CatTree50[[#This Row],[Index 5.0]],'Category List'!B:B,'Category List'!C:C,"") | I18: Done
B19: Climate | C19: Indoor Heaters | D19: Gas Heaters | F19: =_xlfn.TEXTJOIN("-",TRUE,CatTree50[[#This Row],[L1]],CatTree50[[#This Row],[L2]],CatTree50[[#This Row],[L3]],CatTree50[[#This Row],[L4]]) -> Climate-Indoor Heaters-Gas Heaters | G19: Raquel Gonzalez Rodriguez | H19: =_xlfn.XLOOKUP(CatTree50[[#This Row],[Index 5.0]],'Category List'!B:B,'Category List'!C:C,"") | I19: Done
B20: Climate | C20: Indoor Heaters | D20: Heating Blankets | F20: =_xlfn.TEXTJOIN("-",TRUE,CatTree50[[#This Row],[L1]],CatTree50[[#This Row],[L2]],CatTree50[[#This Row],[L3]],CatTree50[[#This Row],[L4]]) -> Climate-Indoor Heaters-Heating Blankets | G20: Raquel Gonzalez Rodriguez | H20: =_xlfn.XLOOKUP(CatTree50[[#This Row],[Index 5.0]],'Category List'!B:B,'Category List'!C:C,"") | I20: Done
B21: Climate | C21: Outdoor Heaters | F21: =_xlfn.TEXTJOIN("-",TRUE,CatTree50[[#This Row],[L1]],CatTree50[[#This Row],[L2]],CatTree50[[#This Row],[L3]],CatTree50[[#This Row],[L4]]) -> Climate-Outdoor Heaters | G21: Raquel Gonzalez Rodriguez | H21: =_xlfn.XLOOKUP(CatTree50[[#This Row],[Index 5.0]],'Category List'!B:B,'Category List'!C:C,"") | I21: Exclude
B22: Climate | C22: Outdoor Heaters | D22: Accessories for Outdoor Heaters | F22: =_xlfn.TEXTJOIN("-",TRUE,CatTree50[[#This Row],[L1]],CatTree50[[#This Row],[L2]],CatTree50[[#This Row],[L3]],CatTree50[[#This Row],[L4]]) -> Climate-Outdoor Heaters-Accessories for Outdoor Heaters | G22: Raquel Gonzalez Rodriguez | H22: =_xlfn.XLOOKUP(CatTree50[[#This Row],[Index 5.0]],'Category List'!B:B,'Category List'!C:C,"") | I22: Exclude
B23: Climate | C23: Outdoor Heaters | D23: Ethanol Heaters | F23: =_xlfn.TEXTJOIN("-",TRUE,CatTree50[[#This Row],[L1]],CatTree50[[#This Row],[L2]],CatTree50[[#This Row],[L3]],CatTree50[[#This Row],[L4]]) -> Climate-Outdoor Heaters-Ethanol Heaters | G23: Raquel Gonzalez Rodriguez | H23: =_xlfn.XLOOKUP(CatTree50[[#This Row],[Index 5.0]],'Category List'!B:B,'Category List'!C:C,"") | I23: Not sure
B24: Garden | F24: =_xlfn.TEXTJOIN("-",TRUE,CatTree50[[#This Row],[L1]],CatTree50[[#This Row],[L2]],CatTree50[[#This Row],[L3]],CatTree50[[#This Row],[L4]]) -> Garden | H24: =_xlfn.XLOOKUP(CatTree50[[#This Row],[Index 5.0]],'Category List'!B:B,'Category List'!C:C,"") | I24: Exclude
B25: Garden | C25: Garden Furniture | F25: =_xlfn.TEXTJOIN("-",TRUE,CatTree50[[#This Row],[L1]],CatTree50[[#This Row],[L2]],CatTree50[[#This Row],[L3]],CatTree50[[#This Row],[L4]]) -> Garden-Garden Furniture | H25: =_xlfn.XLOOKUP(CatTree50[[#This Row],[Index 5.0]],'Category List'!B:B,'Category List'!C:C,"") | I25: Exclude
B26: Garden | C26: Garden Furniture | D26: Accessories for Garden Furniture | F26: =_xlfn.TEXTJOIN("-",TRUE,CatTree50[[#This Row],[L1]],CatTree50[[#This Row],[L2]],CatTree50[[#This Row],[L3]],CatTree50[[#This Row],[L4]]) -> Garden-Garden Furniture-Accessories for Garden Furniture | H26: =_xlfn.XLOOKUP(CatTree50[[#This Row],[Index 5.0]],'Category List'!B:B,'Category List'!C:C,"") | I26: Exclude
B27: Garden | C27: Garden Furniture | D27: Garden Chairs | F27: =_xlfn.TEXTJOIN("-",TRUE,CatTree50[[#This Row],[L1]],CatTree50[[#This Row],[L2]],CatTree50[[#This Row],[L3]],CatTree50[[#This Row],[L4]]) -> Garden-Garden Furniture-Garden Chairs | H27: =_xlfn.XLOOKUP(CatTree50[[#This Row],[Index 5.0]],'Category List'!B:B,'Category List'!C:C,"") | I27: Exclude
B28: Garden | C28: Garden Furniture | D28: Garden Tables | F28: =_xlfn.TEXTJOIN("-",TRUE,CatTree50[[#This Row],[L1]],CatTree50[[#This Row],[L2]],CatTree50[[#This Row],[L3]],CatTree50[[#This Row],[L4]]) -> Garden-Garden Furniture-Garden Tables | H28: =_xlfn.XLOOKUP(CatTree50[[#This Row],[Index 5.0]],'Category List'!B:B,'Category List'!C:C,"") | I28: Exclude
B29: Garden | C29: Garden Furniture | D29: Loungers | F29: =_xlfn.TEXTJOIN("-",TRUE,CatTree50[[#This Row],[L1]],CatTree50[[#This Row],[L2]],CatTree50[[#This Row],[L3]],CatTree50[[#This Row],[L4]]) -> Garden-Garden Furniture-Loungers | H29: =_xlfn.XLOOKUP(CatTree50[[#This Row],[Index 5.0]],'Category List'!B:B,'Category List'!C:C,"") | I29: Exclude
B30: Garden | C30: Garden Furniture | D30: Seating Sets | F30: =_xlfn.TEXTJOIN("-",TRUE,CatTree50[[#This Row],[L1]],CatTree50[[#This Row],[L2]],CatTree50[[#This Row],[L3]],CatTree50[[#This Row],[L4]]) -> Garden-Garden Furniture-Seating Sets | H30: =_xlfn.XLOOKUP(CatTree50[[#This Row],[Index 5.0]],'Category List'!B:B,'Category List'!C:C,"") | I30: Exclude
B31: Garden | C31: Garden Furniture | D31: Sunbeds | F31: =_xlfn.TEXTJOIN("-",TRUE,CatTree50[[#This Row],[L1]],CatTree50[[#This Row],[L2]],CatTree50[[#This Row],[L3]],CatTree50[[#This Row],[L4]]) -> Garden-Garden Furniture-Sunbeds | H31: =_xlfn.XLOOKUP(CatTree50[[#This Row],[Index 5.0]],'Category List'!B:B,'Category List'!C:C,"") | I31: Exclude
B32: Garden | C32: Garden Furniture | D32: Swings | F32: =_xlfn.TEXTJOIN("-",TRUE,CatTree50[[#This Row],[L1]],CatTree50[[#This Row],[L2]],CatTree50[[#This Row],[L3]],CatTree50[[#This Row],[L4]]) -> Garden-Garden Furniture-Swings | H32: =_xlfn.XLOOKUP(CatTree50[[#This Row],[Index 5.0]],'Category List'!B:B,'Category List'!C:C,"") | I32: Exclude
B33: Garden | C33: Garden Structures & Shade | F33: =_xlfn.TEXTJOIN("-",TRUE,CatTree50[[#This Row],[L1]],CatTree50[[#This Row],[L2]],CatTree50[[#This Row],[L3]],CatTree50[[#This Row],[L4]]) -> Garden-Garden Structures & Shade | H33: =_xlfn.XLOOKUP(CatTree50[[#This Row],[Index 5.0]],'Category List'!B:B,'Category List'!C:C,"") | I33: Exclude
B34: Garden | C34: Garden Structures & Shade | D34: Awnings | F34: =_xlfn.TEXTJOIN("-",TRUE,CatTree50[[#This Row],[L1]],CatTree50[[#This Row],[L2]],CatTree50[[#This Row],[L3]],CatTree50[[#This Row],[L4]]) -> Garden-Garden Structures & Shade-Awnings | H34: =_xlfn.XLOOKUP(CatTree50[[#This Row],[Index 5.0]],'Category List'!B:B,'Category List'!C:C,"") | I34: Exclude
B35: Garden | C35: Garden Structures & Shade | D35: Gazebos | F35: =_xlfn.TEXTJOIN("-",TRUE,CatTree50[[#This Row],[L1]],CatTree50[[#This Row],[L2]],CatTree50[[#This Row],[L3]],CatTree50[[#This Row],[L4]]) -> Garden-Garden Structures & Shade-Gazebos | H35: =_xlfn.XLOOKUP(CatTree50[[#This Row],[Index 5.0]],'Category List'!B:B,'Category List'!C:C,"") | I35: Exclude
B36: Garden | C36: Garden Structures & Shade | D36: Privacy Screens | F36: =_xlfn.TEXTJOIN("-",TRUE,CatTree50[[#This Row],[L1]],CatTree50[[#This Row],[L2]],CatTree50[[#This Row],[L3]],CatTree50[[#This Row],[L4]]) -> Garden-Garden Structures & Shade-Privacy Screens | H36: =_xlfn.XLOOKUP(CatTree50[[#This Row],[Index 5.0]],'Category List'!B:B,'Category List'!C:C,"") | I36: Exclude
B37: Garden | C37: Garden Structures & Shade | D37: Umbrellas | F37: =_xlfn.TEXTJOIN("-",TRUE,CatTree50[[#This Row],[L1]],CatTree50[[#This Row],[L2]],CatTree50[[#This Row],[L3]],CatTree50[[#This Row],[L4]]) -> Garden-Garden Structures & Shade-Umbrellas | H37: =_xlfn.XLOOKUP(CatTree50[[#This Row],[Index 5.0]],'Category List'!B:B,'Category List'!C:C,"") | I37: Exclude
B38: Garden | C38: Garden Utilities | F38: =_xlfn.TEXTJOIN("-",TRUE,CatTree50[[#This Row],[L1]],CatTree50[[#This Row],[L2]],CatTree50[[#This Row],[L3]],CatTree50[[#This Row],[L4]]) -> Garden-Garden Utilities | H38: =_xlfn.XLOOKUP(CatTree50[[#This Row],[Index 5.0]],'Category List'!B:B,'Category List'!C:C,"") | I38: Exclude
B39: Garden | C39: Garden Utilities | D39: Breeding Supplies | F39: =_xlfn.TEXTJOIN("-",TRUE,CatTree50[[#This Row],[L1]],CatTree50[[#This Row],[L2]],CatTree50[[#This Row],[L3]],CatTree50[[#This Row],[L4]]) -> Garden-Garden Utilities-Breeding Supplies | H39: =_xlfn.XLOOKUP(CatTree50[[#This Row],[Index 5.0]],'Category List'!B:B,'Category List'!C:C,"") | I39: Exclude
B40: Garden | C40: Garden Utilities | D40: Decorations | F40: =_xlfn.TEXTJOIN("-",TRUE,CatTree50[[#This Row],[L1]],CatTree50[[#This Row],[L2]],CatTree50[[#This Row],[L3]],CatTree50[[#This Row],[L4]]) -> Garden-Garden Utilities-Decorations | H40: =_xlfn.XLOOKUP(CatTree50[[#This Row],[Index 5.0]],'Category List'!B:B,'Category List'!C:C,"") | I40: Exclude
B41: Garden | C41: Garden Utilities | D41: Firewood Stands | F41: =_xlfn.TEXTJOIN("-",TRUE,CatTree50[[#This Row],[L1]],CatTree50[[#This Row],[L2]],CatTree50[[#This Row],[L3]],CatTree50[[#This Row],[L4]]) -> Garden-Garden Utilities-Firewood Stands | G41: Klaudia Weronika Kolodziej | H41: =_xlfn.XLOOKUP(CatTree50[[#This Row],[Index 5.0]],'Category List'!B:B,'Category List'!C:C,"") | I41: Exclude
B42: Garden | C42: Garden Utilities | D42: Fountains | F42: =_xlfn.TEXTJOIN("-",TRUE,CatTree50[[#This Row],[L1]],CatTree50[[#This Row],[L2]],CatTree50[[#This Row],[L3]],CatTree50[[#This Row],[L4]]) -> Garden-Garden Utilities-Fountains | H42: =_xlfn.XLOOKUP(CatTree50[[#This Row],[Index 5.0]],'Category List'!B:B,'Category List'!C:C,"") | I42: Exclude
...

Sheet Briefing
A1: Project ID | B1: Index 3.0 | C1: Column4 | D1: Image 1 | E1: Image 2 | F1: Image 3 | G1: Image 4 | H1: Image 5 | I1: Image 6 | J1: Image 7 | K1: Image 8 | L1: Image 9 | M1: Image 10
A2: MDA25065 | B2: Large Appliances-Cooker Hoods-Angled Wall Hoods | C2: Use as reference: | D2: 1003777
A3: MDA25083 | B3: Large Appliances-Hobs-Hobs - VTC | C3: Use as reference: | D3: 10029239
A4: MDA25083 | B4: Outdoor Living-Pits-Fire Pits | C4: Use as reference: | D4: 10029239
A5: MDA 25079 | C5: Use as reference: | D5: 10032301
A6: MDA 25075 | C6: Use as reference: | D6: 10032902
A7: MDA 25075 | C7: Use as reference: | D7: 10032902
A8: MDA25074 | B8: Large Appliances-Dishwashing-Dishwashers - Built-In/Under | C8: Use as reference: | D8: 10032913
A9: MDA25041 | B9: Large Appliances-Hobs-Hobs - Gas | C9: Use as reference: | D9: 10033132
A10: MDA25041 | C10: Use as reference: | D10: 10033132
A11: PROJECT ID GL25033 | C11: Use as reference: | D11: 10034123
A12: PROJECT ID GL25033 | C12: Use as reference: | D12: 10034123
A13: PROJECT ID GL25033 | B13: Climate-Indoor Heating-Electric Mantel Fireplaces | C13: Use as reference: | D13: 10034123
A14: PROJECT ID GL25033 | C14: Use as reference: | D14: 10034124
A15: PROJECT ID GL25033 | C15: Use as reference: | D15: 10034124
A16: PROJECT ID GL25033 | B16: Climate-Indoor Heating-Electric Mantel Fireplaces | C16: Use as reference: | D16: 10034124
A17: MDA25050 | C17: Use as reference: | D17: 10034604
A18: MDA25050 | B18: Large Appliances-Hobs-Hobs - VTC | C18: Use as reference: | D18: 10034604
A19: MDA25050 | B19: Outdoor Living-Pits-Fire Pits | C19: Use as reference: | D19: 10034604
A20: MDA25021 | B20: Large Appliances-Hobs-Hobs - Induction | C20: Use as reference: | D20: 10034947
A21: MDA25021 | C21: Use as reference: | D21: 10034947
A22: MDA25073 | B22: Large Appliances-Refrigeration-Beverage Coolers | C22: Use as reference: | D22: 10035304
A23: MDA25022 | B23: Large Appliances-Hobs-Hobs - Induction | C23: Use as reference: | D23: 10040202
A24: MDA25022 | C24: Use as reference: | D24: 10040202
A25: MDA25072 | B25: Large Appliances-Refrigeration-Beverage Coolers | C25: Use as reference: | D25: 10041183
A26: SDA25032 | C26: Use as reference: | D26: 10041253
A27: PROJECT ID GL25016 (10048294/5) | B27: Living-Indoor Heating-Radiators | C27: Use as reference: | D27: 10041265 | E27: 10034800 | F27: competitor 1 | G27: competitor 2
A28: MDA25023 | B28: Large Appliances-Hobs-Hobs - Induction | C28: Use as reference: | D28: 10041381
A29: MDA25023 | C29: Use as reference: | D29: 10041381
A30: SDA25014 | B30: Small Appliances-Cold Food Preparation-Ice Cream Makers | C30: Use as reference: | D30: 10045494
A31: MDA25039 | B31: Large Appliances-Hobs-Hobs - Gas | C31: Use as reference: | D31: 10045623
A32: MDA25046 | B32: Large Appliances-Hobs-Hobs w/ Int. Hoods | C32: Use as reference: | D32: 10046231
A33: MDA25046 | B33: Large Appliances-Hobs-Hobs w/ Int. Hoods | C33: Use as reference: | D33: 10046231
A34: MDA 25057 | B34: Large Appliances-Cooker Hoods-Angled Wall Hoods | C34: Use as reference: | D34: 10046377
A35: MDA25061 | B35: Outdoor Living-Pits-Fire Pits | C35: Use as reference: | D35: 10046565
A36: MDA25024 | B36: Large Appliances-Hobs-Hobs - Induction | C36: Use as reference: | D36: 10046565
A37: PROJECT MDA25093 | B37: Large Appliances-Hobs-Hobs - Induction | C37: Use as reference: | D37: 10046565
A38: MDA25093 | B38: Outdoor Living-Pits-Fire Pits | C38: Use as reference: | D38: 10046565
A39: MDA25024 | C39: Use as reference: | D39: 10046565
A40: MDA25044 | B40: Large Appliances-Refrigeration-Beverage Coolers | C40: Use as reference: | D40: 10046633
...

Sheet Category List
B3: Index | C3: SourceFile
B4: Small Appliances-Preserving Pots | C4: Preserving Pots - Attributes V3.0.xlsx
B5: Small Appliances-Pizza Ovens | C5: Pizza Ovens - Attributes V3.0.xlsx
B6: Small Appliances-Pasta Makers | C6: Pasta Makers - Attributes V3.0.xlsx
B7: Small Appliances-Meat Grinders | C7: Meat Grinders - Attributes V3.0.xlsx
B8: Small Appliances-Kitchen Machines-Stand Mixers | C8: Stand Mixers - Attributes V3.0.xlsx
B9: Small Appliances-Kitchen Machines-Mixers | C9: Mixers - Attributes V3.0.xlsx
B10: Small Appliances-Kitchen Machines-Juicers | C10: Juicers - Attributes V3.0.xlsx
B11: Small Appliances-Kitchen Machines-Food Processors | C11: Food Processors - Attributes V3.0.xlsx
B12: Small Appliances-Ice Makers-Ice Crushers | C12: Ice Crushers - Attributes V3.0.xlsx
B13: Small Appliances-Ice Makers-Domestic Ice Makers | C13: Domestic Ice Makers - Attributes V3.0.xlsx
B14: Small Appliances-Ice Makers-Commercial Ice Makers | C14: Commercial Ice Makers - Attributes V3.0.xlsx
... B62: Climate-Air Purifiers | C62: Air Purifiers - Attributes V3.0.xlsx

Sheet Sheet3

Sheet AttributeDictionary
A1: Where to Store | B1: Attribute | C1: Index 3.0 | D1: Attribute ID | E1: SourceFile | F1: SourcePath | G1: Key
B2: Name | C2: Large Appliances-Refrigerators-Portable Refrigerators | D2: Attribute1 | E2: Portable Refrigerators - Attributes V3.0.xlsx | F2: https://chaltecadmin.sharepoint.com/sites/ProductManagement/Shared Documents/02_Strategy/01_Portfolio Strategy/05_Product Passport/01_Large Appliances/ | G2: Attribute1Large Appliances-Refrigerators-Portable Refrigerators
B3: Picture | C3: Large Appliances-Refrigerators-Portable Refrigerators | D3: Attribute2 | E3: Portable Refrigerators - Attributes V3.0.xlsx | F3: https://chaltecadmin.sharepoint.com/sites/ProductManagement/Shared Documents/02_Strategy/01_Portfolio Strategy/05_Product Passport/01_Large Appliances/ | G3: Attribute2Large Appliances-Refrigerators-Portable Refrigerators
B4: e-star | C4: Large Appliances-Refrigerators-Portable Refrigerators | D4: Attribute3 | E4: Portable Refrigerators - Attributes V3.0.xlsx | F4: https://chaltecadmin.sharepoint.com/sites/ProductManagement/Shared Documents/02_Strategy/01_Portfolio Strategy/05_Product Passport/01_Large Appliances/ | G4: Attribute3Large Appliances-Refrigerators-Portable Refrigerators
B5: Family | C5: Large Appliances-Refrigerators-Portable Refrigerators | D5: Attribute4 | E5: Portable Refrigerators - Attributes V3.0.xlsx | F5: https://chaltecadmin.sharepoint.com/sites/ProductManagement/Shared Documents/02_Strategy/01_Portfolio Strategy/05_Product Passport/01_Large Appliances/ | G5: Attribute4Large Appliances-Refrigerators-Portable Refrigerators
B6: EOL | C6: Large Appliances-Refrigerators-Portable Refrigerators | D6: Attribute5 | E6: Portable Refrigerators - Attributes V3.0.xlsx | F6: https://chaltecadmin.sharepoint.com/sites/ProductManagement/Shared Documents/02_Strategy/01_Portfolio Strategy/05_Product Passport/01_Large Appliances/ | G6: Attribute5Large Appliances-Refrigerators-Portable Refrigerators
B7: Supplier | C7: Large Appliances-Refrigerators-Portable Refrigerators | D7: Attribute6 | E7: Portable Refrigerators - Attributes V3.0.xlsx | F7: https://chaltecadmin.sharepoint.com/sites/ProductManagement/Shared Documents/02_Strategy/01_Portfolio Strategy/05_Product Passport/01_Large Appliances/ | G7: Attribute6Large Appliances-Refrigerators-Portable Refrigerators
B8: Data Status | C8: Large Appliances-Refrigerators-Portable Refrigerators | D8: Attribute7 | E8: Portable Refrigerators - Attributes V3.0.xlsx | F8: https://chaltecadmin.sharepoint.com/sites/ProductManagement/Shared Documents/02_Strategy/01_Portfolio Strategy/05_Product Passport/01_Large Appliances/ | G8: Attribute7Large Appliances-Refrigerators-Portable Refrigerators
B9: Upload Status | C9: Large Appliances-Refrigerators-Portable Refrigerators | D9: Attribute8 | E9: Portable Refrigerators - Attributes V3.0.xlsx | F9: https://chaltecadmin.sharepoint.com/sites/ProductManagement/Shared Documents/02_Strategy/01_Portfolio Strategy/05_Product Passport/01_Large Appliances/ | G9: Attribute8Large Appliances-Refrigerators-Portable Refrigerators
B10: Date Last Upload Akeneo | C10: Large Appliances-Refrigerators-Portable Refrigerators | D10: Attribute9 | E10: Portable Refrigerators - Attributes V3.0.xlsx | F10: https://chaltecadmin.sharepoint.com/sites/ProductManagement/Shared Documents/02_Strategy/01_Portfolio Strategy/05_Product Passport/01_Large Appliances/ | G10: Attribute9Large Appliances-Refrigerators-Portable Refrigerators
B11: Category 5.0 & Segmentation | C11: Large Appliances-Refrigerators-Portable Refrigerators | D11: Attribute10 | E11: Portable Refrigerators - Attributes V3.0.xlsx | F11: https://chaltecadmin.sharepoint.com/sites/ProductManagement/Shared Documents/02_Strategy/01_Portfolio Strategy/05_Product Passport/01_Large Appliances/ | G11: Attribute10Large Appliances-Refrigerators-Portable Refrigerators
B12: Index | C12: Large Appliances-Refrigerators-Portable Refrigerators | D12: Attribute11 | E12: Portable Refrigerators - Attributes V3.0.xlsx | F12: https://chaltecadmin.sharepoint.com/sites/ProductManagement/Shared Documents/02_Strategy/01_Portfolio Strategy/05_Product Passport/01_Large Appliances/ | G12: Attribute11Large Appliances-Refrigerators-Portable Refrigerators
A13: SAP | B13: L1 | C13: Large Appliances-Refrigerators-Portable Refrigerators | D13: Attribute12 | E13: Portable Refrigerators - Attributes V3.0.xlsx | F13: https://chaltecadmin.sharepoint.com/sites/ProductManagement/Shared Documents/02_Strategy/01_Portfolio Strategy/05_Product Passport/01_Large Appliances/ | G13: Attribute12Large Appliances-Refrigerators-Portable Refrigerators
A14: SAP | B14: L2 | C14: Large Appliances-Refrigerators-Portable Refrigerators | D14: Attribute13 | E14: Portable Refrigerators - Attributes V3.0.xlsx | F14: https://chaltecadmin.sharepoint.com/sites/ProductManagement/Shared Documents/02_Strategy/01_Portfolio Strategy/05_Product Passport/01_Large Appliances/ | G14: Attribute13Large Appliances-Refrigerators-Portable Refrigerators
A15: SAP | B15: L3 | C15: Large Appliances-Refrigerators-Portable Refrigerators | D15: Attribute14 | E15: Portable Refrigerators - Attributes V3.0.xlsx | F15: https://chaltecadmin.sharepoint.com/sites/ProductManagement/Shared Documents/02_Strategy/01_Portfolio Strategy/05_Product Passport/01_Large Appliances/ | G15: Attribute14Large Appliances-Refrigerators-Portable Refrigerators
A16: SAP | B16: L4 | C16: Large Appliances-Refrigerators-Portable Refrigerators | D16: Attribute15 | E16: Portable Refrigerators - Attributes V3.0.xlsx | F16: https://chaltecadmin.sharepoint.com/sites/ProductManagement/Shared Documents/02_Strategy/01_Portfolio Strategy/05_Product Passport/01_Large Appliances/ | G16: Attribute15Large Appliances-Refrigerators-Portable Refrigerators
A17: Akeneo | B17: Family Name | C17: Large Appliances-Refrigerators-Portable Refrigerators | D17: Attribute16 | E17: Portable Refrigerators - Attributes V3.0.xlsx | F17: https://chaltecadmin.sharepoint.com/sites/ProductManagement/Shared Documents/02_Strategy/01_Portfolio Strategy/05_Product Passport/01_Large Appliances/ | G17: Attribute16Large Appliances-Refrigerators-Portable Refrigerators
A18: Akeneo | B18: Project ID | C18: Large Appliances-Refrigerators-Portable Refrigerators | D18: Attribute17 | E18: Portable Refrigerators - Attributes V3.0.xlsx | F18: https://chaltecadmin.sharepoint.com/sites/ProductManagement/Shared Documents/02_Strategy/01_Portfolio Strategy/05_Product Passport/01_Large Appliances/ | G18: Attribute17Large Appliances-Refrigerators-Portable Refrigerators
A19: Akeneo | B19: Segment 1 | C19: Large Appliances-Refrigerators-Portable Refrigerators | D19: Attribute18 | E19: Portable Refrigerators - Attributes V3.0.xlsx | F19: https://chaltecadmin.sharepoint.com/sites/ProductManagement/Shared Documents/02_Strategy/01_Portfolio Strategy/05_Product Passport/01_Large Appliances/ | G19: Attribute18Large Appliances-Refrigerators-Portable Refrigerators
A20: Akeneo | B20: Segment 2 | C20: Large Appliances-Refrigerators-Portable Refrigerators | D20: Attribute19 | E20: Portable Refrigerators - Attributes V3.0.xlsx | F20: https://chaltecadmin.sharepoint.com/sites/ProductManagement/Shared Documents/02_Strategy/01_Portfolio Strategy/05_Product Passport/01_Large Appliances/ | G20: Attribute19Large Appliances-Refrigerators-Portable Refrigerators
A21: Akeneo | B21: Segment 3 | C21: Large Appliances-Refrigerators-Portable Refrigerators | D21: Attribute20 | E21: Portable Refrigerators - Attributes V3.0.xlsx | F21: https://chaltecadmin.sharepoint.com/sites/ProductManagement/Shared Documents/02_Strategy/01_Portfolio Strategy/05_Product Passport/01_Large Appliances/ | G21: Attribute20Large Appliances-Refrigerators-Portable Refrigerators
A22: Akeneo | B22: Segment 4 | C22: Large Appliances-Refrigerators-Portable Refrigerators | D22: Attribute21 | E22: Portable Refrigerators - Attributes V3.0.xlsx | F22: https://chaltecadmin.sharepoint.com/sites/ProductManagement/Shared Documents/02_Strategy/01_Portfolio Strategy/05_Product Passport/01_Large Appliances/ | G22: Attribute21Large Appliances-Refrigerators-Portable Refrigerators
A23: Akeneo | B23: Segment 5 | C23: Large Appliances-Refrigerators-Portable Refrigerators | D23: Attribute22 | E23: Portable Refrigerators - Attributes V3.0.xlsx | F23: https://chaltecadmin.sharepoint.com/sites/ProductManagement/Shared Documents/02_Strategy/01_Portfolio Strategy/05_Product Passport/01_Large Appliances/ | G23: Attribute22Large Appliances-Refrigerators-Portable Refrigerators
B24: Listing & Data | C24: Large Appliances-Refrigerators-Portable Refrigerators | D24: Attribute23 | E24: Portable Refrigerators - Attributes V3.0.xlsx | F24: https://chaltecadmin.sharepoint.com/sites/ProductManagement/Shared Documents/02_Strategy/01_Portfolio Strategy/05_Product Passport/01_Large Appliances/ | G24: Attribute23Large Appliances-Refrigerators-Portable Refrigerators
A25: SAP | B25: Database Name | C25: Large Appliances-Refrigerators-Portable Refrigerators | D25: Attribute24 | E25: Portable Refrigerators - Attributes V3.0.xlsx | F25: https://chaltecadmin.sharepoint.com/sites/ProductManagement/Shared Documents/02_Strategy/01_Portfolio Strategy/05_Product Passport/01_Large Appliances/ | G25: Attribute24Large Appliances-Refrigerators-Portable Refrigerators
B26: Char Count -> MAX 40 | C26: Large Appliances-Refrigerators-Portable Refrigerators | D26: Attribute25 | E26: Portable Refrigerators - Attributes V3.0.xlsx | F26: https://chaltecadmin.sharepoint.com/sites/ProductManagement/Shared Documents/02_Strategy/01_Portfolio Strategy/05_Product Passport/01_Large Appliances/ | G26: Attribute25Large Appliances-Refrigerators-Portable Refrigerators
B27: Variant with SKU or Family: | C27: Large Appliances-Refrigerators-Portable Refrigerators | D27: Attribute26 | E27: Portable Refrigerators - Attributes V3.0.xlsx | F27: https://chaltecadmin.sharepoint.com/sites/ProductManagement/Shared Documents/02_Strategy/01_Portfolio Strategy/05_Product Passport/01_Large Appliances/ | G27: Attribute26Large Appliances-Refrigerators-Portable Refrigerators
A28: Akeneo | B28: Variation 1 | C28: Large Appliances-Refrigerators-Portable Refrigerators | D28: Attribute27 | E28: Portable Refrigerators - Attributes V3.0.xlsx | F28: https://chaltecadmin.sharepoint.com/sites/ProductManagement/Shared Documents/02_Strategy/01_Portfolio Strategy/05_Product Passport/01_Large Appliances/ | G28: Attribute27Large Appliances-Refrigerators-Portable Refrigerators
A29: Akeneo | B29: Variation 1 - Value | C29: Large Appliances-Refrigerators-Portable Refrigerators | D29: Attribute28 | E29: Portable Refrigerators - Attributes V3.0.xlsx | F29: https://chaltecadmin.sharepoint.com/sites/ProductManagement/Shared Documents/02_Strategy/01_Portfolio Strategy/05_Product Passport/01_Large Appliances/ | G29: Attribute28Large Appliances-Refrigerators-Portable Refrigerators
A30: Akeneo | B30: Variation 2 | C30: Large Appliances-Refrigerators-Portable Refrigerators | D30: Attribute29 | E30: Portable Refrigerators - Attributes V3.0.xlsx | F30: https://chaltecadmin.sharepoint.com/sites/ProductManagement/Shared Documents/02_Strategy/01_Portfolio Strategy/05_Product Passport/01_Large Appliances/ | G30: Attribute29Large Appliances-Refrigerators-Portable Refrigerators
A31: Akeneo | B31: Variation 2 - Value | C31: Large Appliances-Refrigerators-Portable Refrigerators | D31: Attribute30 | E31: Portable Refrigerators - Attributes V3.0.xlsx | F31: https://chaltecadmin.sharepoint.com/sites/ProductManagement/Shared Documents/02_Strategy/01_Portfolio Strategy/05_Product Passport/01_Large Appliances/ | G31: Attribute30Large Appliances-Refrigerators-Portable Refrigerators
A32: Akeneo | B32: Variation 3 | C32: Large Appliances-Refrigerators-Portable Refrigerators | D32: Attribute31 | E32: Portable Refrigerators - Attributes V3.0.xlsx | F32: https://chaltecadmin.sharepoint.com/sites/ProductManagement/Shared Documents/02_Strategy/01_Portfolio Strategy/05_Product Passport/01_Large Appliances/ | G32: Attribute31Large Appliances-Refrigerators-Portable Refrigerators
A33: Akeneo | B33: Variation 3 - Value | C33: Large Appliances-Refrigerators-Portable Refrigerators | D33: Attribute32 | E33: Portable Refrigerators - Attributes V3.0.xlsx | F33: https://chaltecadmin.sharepoint.com/sites/ProductManagement/Shared Documents/02_Strategy/01_Portfolio Strategy/05_Product Passport/01_Large Appliances/ | G33: Attribute32Large Appliances-Refrigerators-Portable Refrigerators
B34: 1 . Category Specific Attributes | C34: Large Appliances-Refrigerators-Portable Refrigerators | D34: Attribute33 | E34: Portable Refrigerators - Attributes V3.0.xlsx | F34: https://chaltecadmin.sharepoint.com/sites/ProductManagement/Shared Documents/02_Strategy/01_Portfolio Strategy/05_Product Passport/01_Large Appliances/ | G34: Attribute33Large Appliances-Refrigerators-Portable Refrigerators
A35: SAP | B35: Supplier Part Number | C35: Large Appliances-Refrigerators-Portable Refrigerators | D35: Attribute34 | E35: Portable Refrigerators - Attributes V3.0.xlsx | F35: https://chaltecadmin.sharepoint.com/sites/ProductManagement/Shared Documents/02_Strategy/01_Portfolio Strategy/05_Product Passport/01_Large Appliances/ | G35: Attribute34Large Appliances-Refrigerators-Portable Refrigerators
A36: Akeneo | B36: Nominal capacity [L] | C36: Large Appliances-Refrigerators-Portable Refrigerators | D36: Attribute35 | E36: Portable Refrigerators - Attributes V3.0.xlsx | F36: https://chaltecadmin.sharepoint.com/sites/ProductManagement/Shared Documents/02_Strategy/01_Portfolio Strategy/05_Product Passport/01_Large Appliances/ | G36: Attribute35Large Appliances-Refrigerators-Portable Refrigerators
A37: Akeneo | B37: Compartment [Single, Dual] | C37: Large Appliances-Refrigerators-Portable Refrigerators | D37: Attribute36 | E37: Portable Refrigerators - Attributes V3.0.xlsx | F37: https://chaltecadmin.sharepoint.com/sites/ProductManagement/Shared Documents/02_Strategy/01_Portfolio Strategy/05_Product Passport/01_Large Appliances/ | G37: Attribute36Large Appliances-Refrigerators-Portable Refrigerators
A38: Akeneo | B38: Dual Zone Control [Y/N] | C38: Large Appliances-Refrigerators-Portable Refrigerators | D38: Attribute37 | E38: Portable Refrigerators - Attributes V3.0.xlsx | F38: https://chaltecadmin.sharepoint.com/sites/ProductManagement/Shared Documents/02_Strategy/01_Portfolio Strategy/05_Product Passport/01_Large Appliances/ | G38: Attribute37Large Appliances-Refrigerators-Portable Refrigerators
B39: Type of cooling system | C39: Large Appliances-Refrigerators-Portable Refrigerators | D39: Attribute38 | E39: Portable Refrigerators - Attributes V3.0.xlsx | F39: https://chaltecadmin.sharepoint.com/sites/ProductManagement/Shared Documents/02_Strategy/01_Portfolio Strategy/05_Product Passport/01_Large Appliances/ | G39: Attribute38Large Appliances-Refrigerators-Portable Refrigerators
B40: Refrigerant Type | C40: Large Appliances-Refrigerators-Portable Refrigerators | D40: Attribute39 | E40: Portable Refrigerators - Attributes V3.0.xlsx | F40: https://chaltecadmin.sharepoint.com/sites/ProductManagement/Shared Documents/02_Strategy/01_Portfolio Strategy/05_Product Passport/01_Large Appliances/ | G40: Attribute39Large Appliances-Refrigerators-Portable Refrigerators
...

Sheet SKUAttributes
